<?xml version="1.0" encoding="utf-8"?>
<!-- This URDF was automatically created by SolidWorks to URDF Exporter! Originally created by Stephen Brawner (brawner@gmail.com) 
     Commit Version: 1.6.0-4-g7f85cfe  Build Version: 1.6.7995.38578
     For more information, please see http://wiki.ros.org/sw_urdf_exporter -->
<robot name="inspire_hand_r" xmlns:xacro="http://ros.org/wiki/xacro">
  
  name="inspire_hand_r">
  <link name="world" />
  <link
    name="base_link">
    <inertial>
      <origin
        xyz="-2.15561648839006E-08 -0.00191999281804056 0.0332314676154005"
        rpy="0 0 0" />
      <mass
        value="0.0695038586391028" />
      <inertia
        ixx="3.10214944966728E-05"
        ixy="6.95199575783958E-11"
        ixz="-1.97073434557092E-11"
        iyy="3.02480661265027E-05"
        iyz="-5.01501324812038E-07"
        izz="2.86515730078329E-05" />
    </inertial>
    <visual>
      <origin
        xyz="0 0 0"
        rpy="0 0 0" />
      <geometry>
        <mesh
          filename="package://inspire_hand_r/meshes/base_link.STL" />
      </geometry>
      <material
        name="">
        <color
          rgba="0.894117647058823 0.913725490196078 0.929411764705882 1" />
      </material>
    </visual>
    <collision>
      <origin
        xyz="0 0 0"
        rpy="0 0 0" />
      <geometry>
        <mesh
          filename="package://inspire_hand_r/meshes/base_link.STL" />
      </geometry>
    </collision>
  </link>
  <joint
      name="fixed_base_joint"
      type="fixed"> 
    <origin
      xyz="0 0 0.001"
      rpy="0 0 0" />
    <parent link="world" />
    <child link="base_link" />
  </joint>
  <link
    name="Link_1">
    <inertial>
      <origin
        xyz="-0.0133419951922048 0.00575897820477875 -0.000150000894158946"
        rpy="0 0 0" />
      <mass
        value="0.00277890585457231" />
      <inertia
        ixx="1.09370485183287E-07"
        ixy="-1.48845839380445E-08"
        ixz="1.04480163452976E-14"
        iyy="1.49079739934158E-07"
        iyz="1.24013950499517E-15"
        izz="2.26417228011718E-07" />
    </inertial>
    <visual>
      <origin
        xyz="0 0 0"
        rpy="0 0 0" />
      <geometry>
        <mesh
          filename="package://inspire_hand_r/meshes/Link_1.STL" />
      </geometry>
      <material
        name="">
        <color
          rgba="0 1 1 1" />
      </material>
    </visual>
    <collision>
      <origin
        xyz="0 0 0"
        rpy="0 0 0" />
      <geometry>
        <mesh
          filename="package://inspire_hand_r/meshes/Link_1.STL" />
      </geometry>
    </collision>
  </link>
  <joint
    name="joint_1"
    type="revolute">
    <origin
      xyz="0.00015 0.00565 0.0782"
      rpy="1.5708 0 1.5708" />
    <parent
      link="base_link" />
    <child
      link="Link_1" />
    <axis
      xyz="-1 0 0" />
    <limit
      lower="-0.445"
      upper="0.445"
      effort="10"
      velocity="1" />
  </joint>
  <link
    name="Link_11">
    <inertial>
      <origin
        xyz="-0.00201547733411032 0.0510150201977158 -0.0137687123591791"
        rpy="0 0 0" />
      <mass
        value="0.141506121776802" />
      <inertia
        ixx="0.000109733477753849"
        ixy="2.40417904196419E-06"
        ixz="-1.74223281691751E-06"
        iyy="6.73457792880789E-05"
        iyz="1.87121289681864E-06"
        izz="7.13073727664869E-05" />
    </inertial>
    <visual>
      <origin
        xyz="0 0 0"
        rpy="0 0 0" />
      <geometry>
        <mesh
          filename="package://inspire_hand_r/meshes/Link_11.STL" />
      </geometry>
      <material
        name="">
        <color
          rgba="0.894117647058823 0.913725490196078 0.929411764705882 1" />
      </material>
    </visual>
    <collision>
      <origin
        xyz="0 0 0"
        rpy="0 0 0" />
      <geometry>
        <mesh
          filename="package://inspire_hand_r/meshes/Link_11.STL" />
      </geometry>
    </collision>
  </link>
  <joint
    name="joint_11"
    type="revolute">
    <origin
      xyz="-0.00565 0.0003 -0.01515"
      rpy="3.1416 0 -3.1416" />
    <parent
      link="Link_1" />
    <child
      link="Link_11" />
    <axis
      xyz="0 0 -1" />
    <limit
      lower="-0.3955"
      upper="0.386"
      effort="10"
      velocity="1" />
  </joint>
  <link
    name="R_thumb_proximal_base">
    <inertial>
      <origin
        xyz="-0.0048772 -0.010163 0.00044069"
        rpy="0 -3.1415926 0" />
      <mass
        value="0.0018869" />
      <inertia
        ixx="5.2002E-08"
        ixy="4.8353E-09"
        ixz="-6.6441E-09"
        iyy="6.7433E-08"
        iyz="5.4472E-10"
        izz="8.5319E-08" />
    </inertial>
    <visual>
      <origin
        xyz="0 0 0"
        rpy="0 0 0" />
      <geometry>
        <mesh
          filename="package://inspire_hand_r/meshes/R_thumb_proximal_base.STL" />
      </geometry>
      <material
        name="">
        <color
          rgba="1 1 1 1" />
      </material>
    </visual>
    <collision>
      <origin
        xyz="0 0 0"
        rpy="0 0 0" />
      <geometry>
        <mesh
          filename="package://inspire_hand_r/meshes/R_thumb_proximal_base.STL" />
      </geometry>
    </collision>
  </link>
  <joint
    name="R_thumb_MCP_joint1"
    type="revolute">
    <origin
      xyz="0.020450106 0.0395 -0.04"
      rpy="0 -1.57 0" />
    <parent
      link="Link_11" />
    <child
      link="R_thumb_proximal_base" />
    <axis
      xyz="0 -1 0" />
    <limit
      lower="0"
      upper="1.1"
      effort="50"
      velocity="1" />
  </joint>
  <link
    name="R_thumb_proximal">
    <inertial>
      <origin
        xyz="-3.8592E-05 0.02533 -0.0017007"
        rpy="0 0 0" />
      <mass
        value="0.0066075" />
      <inertia
        ixx="2.786E-06"
        ixy="1.673E-10"
        ixz="-1.3436E-09"
        iyy="8.9422E-07"
        iyz="-2.1394E-07"
        izz="2.4097E-06" />
    </inertial>
    <visual>
      <origin
        xyz="0 0 0"
        rpy="0 0 0" />
      <geometry>
        <mesh
          filename="package://inspire_hand_r/meshes/R_thumb_proximal.STL" />
      </geometry>
      <material
        name="">
        <color
          rgba="1 1 1 1" />
      </material>
    </visual>
    <collision>
      <origin
        xyz="0 0 0"
        rpy="0 0 0" />
      <geometry>
        <mesh
          filename="package://inspire_hand_r/meshes/R_thumb_proximal.STL" />
      </geometry>
    </collision>
  </link>
  <joint
    name="R_thumb_MCP_joint2"
    type="revolute">
    <origin
      xyz="-0.0115 -0.011843 0"
      rpy="5.55298075 1.5708 0" />
    <parent
      link="R_thumb_proximal_base" />
    <child
      link="R_thumb_proximal" />
    <axis
      xyz="1 0 0" />
    <limit
      lower="0"
      upper="0.5"
      effort="50"
      velocity="1" />
  </joint>
  <link
    name="R_thumb_intermediate">
    <inertial>
      <origin
        xyz="2.8437E-07 0.0072526 -0.0064293"
        rpy="0 0 0" />
      <mass
        value="0.0037847" />
      <inertia
        ixx="4.6531E-07"
        ixy="-3.454E-12"
        ixz="3.4344E-12"
        iyy="2.6858E-07"
        iyz="-6.414E-08"
        izz="4.2517E-07" />
    </inertial>
    <visual>
      <origin
        xyz="0 0 0"
        rpy="0 0 0" />
      <geometry>
        <mesh
          filename="package://inspire_hand_r/meshes/R_thumb_intermediate.STL" />
      </geometry>
      <material
        name="">
        <color
          rgba="1 1 1 1" />
      </material>
    </visual>
    <collision>
      <origin
        xyz="0 0 0"
        rpy="0 0 0" />
      <geometry>
        <mesh
          filename="package://inspire_hand_r/meshes/R_thumb_intermediate.STL" />
      </geometry>
    </collision>
  </link>
  <joint
    name="R_thumb_PIP_joint"
    type="revolute">
    <origin
      xyz="0 0.055863 0.0039241"
      rpy="-0.038299 0 0" />
    <parent
      link="R_thumb_proximal" />
    <child
      link="R_thumb_intermediate" />
    <axis
      xyz="1 0 0" />
    <limit
      lower="0"
      upper="1"
      effort="50"
      velocity="1" />
      <mimic 
        joint="R_thumb_MCP_joint2"
        multiplier="0.6"
        offset="0" />
  </joint>
  <link
    name="R_thumb_distal">
    <inertial>
      <origin
        xyz="-3.3054E-06 0.010511 -0.00057863"
        rpy="0 0 0" />
      <mass
        value="0.0033441" />
      <inertia
        ixx="2.0026E-07"
        ixy="-1.4303E-10"
        ixz="-5.6945E-11"
        iyy="8.711E-08"
        iyz="-2.4416E-08"
        izz="1.8974E-07" />
    </inertial>
    <visual>
      <origin
        xyz="0 0 0"
        rpy="0 0 0" />
      <geometry>
        <mesh
          filename="package://inspire_hand_r/meshes/R_thumb_distal.STL" />
      </geometry>
      <material
        name="">
        <color
          rgba="1 1 1 1" />
      </material>
    </visual>
    <collision>
      <origin
        xyz="0 0 0"
        rpy="0 0 0" />
      <geometry>
        <mesh
          filename="package://inspire_hand_r/meshes/R_thumb_distal.STL" />
      </geometry>
    </collision>
  </link>
  <joint
    name="R_thumb_DIP_joint"
    type="revolute">
    <origin
      xyz="0 0.022558 -0.0020717"
      rpy="-0.011642 0 0" />
    <parent
      link="R_thumb_intermediate" />
    <child
      link="R_thumb_distal" />
    <axis
      xyz="1 0 0" />
    <limit
      lower="0"
      upper="1.2"
      effort="50"
      velocity="1" />
      <mimic 
        joint="R_thumb_MCP_joint2"
        multiplier="0.8"
        offset="0" />
  </joint>
  <link
    name="R_index_proximal">
    <inertial>
      <origin
        xyz="0.0099008 0.011884 0.0016958"
        rpy="0 0 0" />
      <mass
        value="0.0042403" />
      <inertia
        ixx="6.9398E-07"
        ixy="-4.4846E-12"
        ixz="-3.0248E-12"
        iyy="2.3039E-07"
        iyz="-9.1779E-08"
        izz="6.434E-07" />
    </inertial>
    <visual>
      <origin
        xyz="0 0 0"
        rpy="0 0 0" />
      <geometry>
        <mesh
          filename="package://inspire_hand_r/meshes/R_index_proximal.STL" />
      </geometry>
      <material
        name="">
        <color
          rgba="1 1 1 1" />
      </material>
    </visual>
    <collision>
      <origin
        xyz="0 0 0"
        rpy="0 0 0" />
      <geometry>
        <mesh
          filename="package://inspire_hand_r/meshes/R_index_proximal.STL" />
      </geometry>
    </collision>
  </link>
  <joint
    name="R_index_MCP_joint"
    type="revolute">
    <origin
      xyz="-0.001114894 0.105 -0.032"
      rpy="-0.25 1.57 0" />
    <parent
      link="Link_11" />
    <child
      link="R_index_proximal" />
    <axis
      xyz="1 0 0" />
    <limit
      lower="0"
      upper="1.7"
      effort="50"
      velocity="1" />
  </joint>
  <link
    name="R_index_distal">
    <inertial>
      <origin
        xyz="0.0083258 0.019591 0.0019565"
        rpy="0 0 0" />
      <mass
        value="0.0045683" />
      <inertia
        ixx="7.8179E-07"
        ixy="9.0022E-13"
        ixz="5.6729E-13"
        iyy="1.5635E-07"
        iyz="-2.1007E-07"
        izz="7.0084E-07" />
    </inertial>
    <visual>
      <origin
        xyz="0 0 0"
        rpy="0 0 0" />
      <geometry>
        <mesh
          filename="package://inspire_hand_r/meshes/R_index_distal.STL" />
      </geometry>
      <material
        name="">
        <color
          rgba="1 1 1 1" />
      </material>
    </visual>
    <collision>
      <origin
        xyz="0 0 0"
        rpy="0 0 0" />
      <geometry>
        <mesh
          filename="package://inspire_hand_r/meshes/R_index_distal.STL" />
      </geometry>
    </collision>
  </link>
  <joint
    name="R_index_DIP_joint"
    type="revolute">
    <origin
      xyz="0.001575 0.030445 0.010275"
      rpy="0.044288 0 0" />
    <parent
      link="R_index_proximal" />
    <child
      link="R_index_distal" />
    <axis
      xyz="1 0 0" />
    <limit
      lower="0"
      upper="1.6"
      effort="50"
      velocity="1" />
      <mimic 
        joint="R_index_MCP_joint"
        multiplier="1"
        offset="0" />
  </joint>
  <link
    name="R_middle_proximal">
    <inertial>
      <origin
        xyz="0.008065 0.011884 0.0016958"
        rpy="0 0 0" />
      <mass
        value="0.0042403" />
      <inertia
        ixx="6.9397E-07"
        ixy="-6.0276E-12"
        ixz="-3.3971E-12"
        iyy="2.3039E-07"
        iyz="-9.1777E-08"
        izz="6.4339E-07" />
    </inertial>
    <visual>
      <origin
        xyz="0 0 0"
        rpy="0 0 0" />
      <geometry>
        <mesh
          filename="package://inspire_hand_r/meshes/R_middle_proximal.STL" />
      </geometry>
      <material
        name="">
        <color
          rgba="1 1 1 1" />
      </material>
    </visual>
    <collision>
      <origin
        xyz="0 0 0"
        rpy="0 0 0" />
      <geometry>
        <mesh
          filename="package://inspire_hand_r/meshes/R_middle_proximal.STL" />
      </geometry>
    </collision>
  </link>
  <joint
    name="R_middle_MCP_joint"
    type="revolute">
    <origin
      xyz="-0.001114894 0.105 -0.0148"
      rpy="-0.25 1.57 0" />
    <parent
      link="Link_11" />
    <child
      link="R_middle_proximal" />
    <axis
      xyz="1 0 0" />
    <limit
      lower="0"
      upper="1.68"
      effort="50"
      velocity="1" />
  </joint>
  <link
    name="R_middle_distal">
    <inertial>
      <origin
        xyz="0.0063978 0.020807 0.0018039"
        rpy="0 0 0" />
      <mass
        value="0.0050396" />
      <inertia
        ixx="9.8384E-07"
        ixy="5.3828E-12"
        ixz="3.4908E-12"
        iyy="1.7328E-07"
        iyz="-2.5594E-07"
        izz="8.914E-07" />
    </inertial>
    <visual>
      <origin
        xyz="0 0 0"
        rpy="0 0 0" />
      <geometry>
        <mesh
          filename="package://inspire_hand_r/meshes/R_middle_distal.STL" />
      </geometry>
      <material
        name="">
        <color
          rgba="1 1 1 1" />
      </material>
    </visual>
    <collision>
      <origin
        xyz="0 0 0"
        rpy="0 0 0" />
      <geometry>
        <mesh
          filename="package://inspire_hand_r/meshes/R_middle_distal.STL" />
      </geometry>
    </collision>
  </link>
  <joint
    name="R_middle_DIP_joint"
    type="revolute">
    <origin
      xyz="0.0016673 0.030445 0.010275"
      rpy="0.071413 0 0" />
    <parent
      link="R_middle_proximal" />
    <child
      link="R_middle_distal" />
    <axis
      xyz="1 0 0" />
    <limit
      lower="0"
      upper="1.6"
      effort="50"
      velocity="1" />
      <mimic 
        joint="R_middle_MCP_joint"
        multiplier="1"
        offset="0" />
  </joint>
  <link
    name="R_ring_proximal">
    <inertial>
      <origin
        xyz="0.0080207 0.011884 0.0016959"
        rpy="0 0 0" />
      <mass
        value="0.0042403" />
      <inertia
        ixx="6.9397E-07"
        ixy="-6.088E-12"
        ixz="-3.1846E-12"
        iyy="2.3039E-07"
        iyz="-9.1776E-08"
        izz="6.4339E-07" />
    </inertial>
    <visual>
      <origin
        xyz="0 0 0"
        rpy="0 0 0" />
      <geometry>
        <mesh
          filename="package://inspire_hand_r/meshes/R_ring_proximal.STL" />
      </geometry>
      <material
        name="">
        <color
          rgba="1 1 1 1" />
      </material>
    </visual>
    <collision>
      <origin
        xyz="0 0 0"
        rpy="0 0 0" />
      <geometry>
        <mesh
          filename="package://inspire_hand_r/meshes/R_ring_proximal.STL" />
      </geometry>
    </collision>
  </link>
  <joint
    name="R_ring_MCP_joint"
    type="revolute">
    <origin
      xyz="-0.001114894 0.105 0.0042"
      rpy="-0.25 1.57 0" />
    <parent
      link="Link_11" />
    <child
      link="R_ring_proximal" />
    <axis
      xyz="1 0 0" />
    <limit
      lower="0"
      upper="1.7"
      effort="50"
      velocity="1" />
  </joint>
  <link
    name="R_ring_distal">
    <inertial>
      <origin
        xyz="0.0080209 0.019591 0.0019565"
        rpy="0 0 0" />
      <mass
        value="0.0045683" />
      <inertia
        ixx="7.8177E-07"
        ixy="4.448E-13"
        ixz="7.2441E-13"
        iyy="1.5635E-07"
        iyz="-2.1007E-07"
        izz="7.0082E-07" />
    </inertial>
    <visual>
      <origin
        xyz="0 0 0"
        rpy="0 0 0" />
      <geometry>
        <mesh
          filename="package://inspire_hand_r/meshes/R_ring_distal.STL" />
      </geometry>
      <material
        name="">
        <color
          rgba="1 1 1 1" />
      </material>
    </visual>
    <collision>
      <origin
        xyz="0 0 0"
        rpy="0 0 0" />
      <geometry>
        <mesh
          filename="package://inspire_hand_r/meshes/R_ring_distal.STL" />
      </geometry>
    </collision>
  </link>
  <joint
    name="R_ring_DIP_joint"
    type="revolute">
    <origin
      xyz="0 0.030445 0.010275"
      rpy="0.039748 0 0" />
    <parent
      link="R_ring_proximal" />
    <child
      link="R_ring_distal" />
    <axis
      xyz="1 0 0" />
    <limit
      lower="0"
      upper="1.6"
      effort="50"
      velocity="1" />
      <mimic 
        joint="R_ring_MCP_joint"
        multiplier="1"
        offset="0" />
  </joint>
  <link
    name="R_pinky_proximal">
    <inertial>
      <origin
        xyz="-0.00109857746425979 0.0119539776675407 -0.00599985649237321"
        rpy="0 0 0" />
      <mass
        value="0.0042403380627586" />
      <inertia
        ixx="6.62603679732664E-07"
        ixy="1.09703050225313E-08"
        ixz="1.78060753387509E-12"
        iyy="2.1117956833567E-07"
        iyz="6.56464477026846E-12"
        izz="6.9397827435971E-07" />
    </inertial>
    <visual>
      <origin
        xyz="0 0 0"
        rpy="0 0 0" />
      <geometry>
        <mesh
          filename="package://inspire_hand_r/meshes/R_pinky_proximal.STL" />
      </geometry>
      <material
        name="">
        <color
          rgba="1 1 1 1" />
      </material>
    </visual>
    <collision>
      <origin
        xyz="0 0 0"
        rpy="0 0 0" />
      <geometry>
        <mesh
          filename="package://inspire_hand_r/meshes/R_pinky_proximal.STL" />
      </geometry>
    </collision>
  </link>
  <joint
    name="R_pinky_MCP_joint"
    type="revolute">
    <origin
      xyz="-0.001114894 0.105 0.0218"
      rpy="0.11 0 0" />
    <parent
      link="Link_11" />
    <child
      link="R_pinky_proximal" />
    <axis
      xyz="0 0 -1" />
    <limit
      lower="0"
      upper="1.7"
      effort="10"
      velocity="1" />
  </joint>
  <link
    name="R_pinky_distal">
    <inertial>
      <origin
        xyz="0.0162003808271628 0.00249068240414548 -0.00499685545685422"
        rpy="0 0 0" />
      <mass
        value="0.00359958667326049" />
      <inertia
        ixx="7.01659328003998E-08"
        ixy="4.10553434047921E-08"
        ixz="-5.85717741286973E-11"
        iyy="4.39207898863221E-07"
        iyz="-3.72226275574817E-11"
        izz="4.48674555889475E-07" />
    </inertial>
    <visual>
      <origin
        xyz="0 0 0"
        rpy="0 0 0" />
      <geometry>
        <mesh
          filename="package://inspire_hand_r/meshes/R_pinky_distal.STL" />
      </geometry>
      <material
        name="">
        <color
          rgba="1 1 1 1" />
      </material>
    </visual>
    <collision>
      <origin
        xyz="0 0 0"
        rpy="0 0 0" />
      <geometry>
        <mesh
          filename="package://inspire_hand_r/meshes/R_pinky_distal.STL" />
      </geometry>
    </collision>
  </link>
  <joint
    name="R_pinky_DIP_joint"
    type="revolute">
    <origin
      xyz="0.0029548 0.031996 -0.001"
      rpy="0 0 1.5708" />
    <parent
      link="R_pinky_proximal" />
    <child
      link="R_pinky_distal" />
    <axis
      xyz="0 0 -1" />
    <limit
      lower="0"
      upper="1.6"
      effort="10"
      velocity="1" />
      <mimic 
        joint="R_pinky_MCP_joint"
        multiplier="1"
        offset="0" />
  </joint>
  
 <xacro:macro name="controller_plugin_gazebo" params="robot_namespace:=''">
 <gazebo>
   <plugin name="gazebo_ros_control" filename="libgazebo_ros_control.so">
    <robotNamespace>/</robotNamespace>
    <legacyModeNS>true</legacyModeNS>
    <controlPeriod>0.001</controlPeriod>
    <robotSimType>gazebo_ros_control/DefaultRobotHWSim</robotSimType>
   </plugin>
  </gazebo>
  </xacro:macro>
  
  <xacro:controller_plugin_gazebo />
  
  
  <!--Transmission for Ros Control-->
  <xacro:macro name="transmission_block" params="joint_name">
  <transmission name="tran1">
   <type>transmission_interface/SimpleTransmission</type>
   <joint name="${joint_name}">
    <hardwareInterface>hardware_interface/PositionJointInterface</hardwareInterface>
   </joint>
   <actuator name="motor1">
    <hardwareInterface>hardware_interface/PositionJointInterface</hardwareInterface>
    <mechanicalReduction>1</mechanicalReduction>
   </actuator>
  </transmission>
  </xacro:macro>

  <xacro:transmission_block joint_name="joint_1"/>  
  <xacro:transmission_block joint_name="joint_11"/>
  <xacro:transmission_block joint_name="R_thumb_MCP_joint1"/>
  <xacro:transmission_block joint_name="R_thumb_MCP_joint2"/>
  <xacro:transmission_block joint_name="R_index_MCP_joint"/>
  <xacro:transmission_block joint_name="R_middle_MCP_joint"/>
  <xacro:transmission_block joint_name="R_ring_MCP_joint"/>
  <xacro:transmission_block joint_name="R_pinky_MCP_joint"/>
  
  <xacro:macro name="mimic_joint_plugin_gazebo" params="name_prefix parent_joint mimic_joint has_pid:=false multiplier:=1.0 offset:=0 sensitiveness:=0.0 max_effort:=1.0 robot_namespace:=''">
    <gazebo>
      <plugin name="${name_prefix}_mimic_joint_plugin" filename="libroboticsgroup_gazebo_mimic_joint_plugin.so">
        <joint>${parent_joint}</joint>
        <mimicJoint>${mimic_joint}</mimicJoint>
        <xacro:if value="${has_pid}">  
          <hasPID />
        </xacro:if>
        <multiplier>${multiplier}</multiplier>
        <offset>${offset}</offset>
        <sensitiveness>${sensitiveness}</sensitiveness>
        <maxEffort>${max_effort}</maxEffort> 
        <xacro:unless value="${robot_namespace == ''}">
          <robotNamespace>${robot_namespace}</robotNamespace>
        </xacro:unless>
      </plugin>
    </gazebo>
  </xacro:macro>

  <xacro:mimic_joint_plugin_gazebo name_prefix="R_index_DIP_joint"
    parent_joint="R_index_MCP_joint" mimic_joint="R_index_DIP_joint"
    has_pid="true" multiplier="1.0" max_effort="10.0" />
    
  <xacro:mimic_joint_plugin_gazebo name_prefix="R_thumb_PIP_joint"
    parent_joint="R_thumb_MCP_joint2" mimic_joint="R_thumb_PIP_joint"
    has_pid="true" multiplier="1.0" max_effort="10.0" />
    
  <xacro:mimic_joint_plugin_gazebo name_prefix="R_thumb_DIP_joint"
    parent_joint="R_thumb_MCP_joint2" mimic_joint="R_thumb_DIP_joint"
    has_pid="true" multiplier="1.0" max_effort="10.0" />
    
  <xacro:mimic_joint_plugin_gazebo name_prefix="R_middle_DIP_joint"
    parent_joint="R_middle_MCP_joint" mimic_joint="R_middle_DIP_joint"
    has_pid="true" multiplier="1.0" max_effort="10.0" />
    
  <xacro:mimic_joint_plugin_gazebo name_prefix="R_ring_DIP_joint"
    parent_joint="R_ring_MCP_joint" mimic_joint="R_ring_DIP_joint"
    has_pid="true" multiplier="1.0" max_effort="10.0" />
    
  <xacro:mimic_joint_plugin_gazebo name_prefix="R_pinky_DIP_joint"
    parent_joint="R_pinky_MCP_joint" mimic_joint="R_pinky_DIP_joint"
    has_pid="true" multiplier="1.0" max_effort="10.0" />
  
</robot>
