<?xml version="1.0" encoding="utf-8"?>
<robot
  name="wrist_base_link_1">
  <link
    name="base_link">
    <inertial>
      <origin
        xyz="-2.15561648839006E-08 -0.00191999281804056 0.0332314676154005"
        rpy="0 0 0" />
      <mass
        value="0.0695038586391028" />
      <inertia
        ixx="3.10214944966728E-05"
        ixy="6.95199575783958E-11"
        ixz="-1.97073434557092E-11"
        iyy="3.02480661265027E-05"
        iyz="-5.01501324812038E-07"
        izz="2.86515730078329E-05" />
    </inertial>
    <visual>
      <origin
        xyz="0 0 0"
        rpy="0 0 0" />
      <geometry>
        <mesh
          filename="package://wrist_base_link_1/meshes/base_link.STL" />
      </geometry>
      <material
        name="">
        <color
          rgba="0.894117647058823 0.913725490196078 0.929411764705882 1" />
      </material>
    </visual>
    <collision>
      <origin
        xyz="0 0 0"
        rpy="0 0 0" />
      <geometry>
        <mesh
          filename="package://wrist_base_link_1/meshes/base_link.STL" />
      </geometry>
    </collision>
  </link>
  <link
    name="Link_1">
    <inertial>
      <origin
        xyz="-0.0133419951922048 0.00575897820477875 -0.000150000894158946"
        rpy="0 0 0" />
      <mass
        value="0.00277890585457231" />
      <inertia
        ixx="1.09370485183287E-07"
        ixy="-1.48845839380445E-08"
        ixz="1.04480163452976E-14"
        iyy="1.49079739934158E-07"
        iyz="1.24013950499517E-15"
        izz="2.26417228011718E-07" />
    </inertial>
    <visual>
      <origin
        xyz="0 0 0"
        rpy="0 0 0" />
      <geometry>
        <mesh
          filename="package://wrist_base_link_1/meshes/Link_1.STL" />
      </geometry>
      <material
        name="">
        <color
          rgba="0 1 1 1" />
      </material>
    </visual>
    <collision>
      <origin
        xyz="0 0 0"
        rpy="0 0 0" />
      <geometry>
        <mesh
          filename="package://wrist_base_link_1/meshes/Link_1.STL" />
      </geometry>
    </collision>
  </link>
  <joint
    name="joint_1"
    type="revolute">
    <origin
      xyz="0.00015 0.00565 0.0782"
      rpy="1.5708 0 1.5708" />
    <parent
      link="base_link" />
    <child
      link="Link_1" />
    <axis
      xyz="-1 0 0" />
    <limit
      lower="-0.445"
      upper="0.445"
      effort="10"
      velocity="1" />
  </joint>
  <link
    name="Link_11">
    <inertial>
      <origin
        xyz="-0.00201547733411032 0.0510150201977158 -0.0137687123591791"
        rpy="0 0 0" />
      <mass
        value="0.141506121776802" />
      <inertia
        ixx="0.000109733477753849"
        ixy="2.40417904196419E-06"
        ixz="-1.74223281691751E-06"
        iyy="6.73457792880789E-05"
        iyz="1.87121289681864E-06"
        izz="7.13073727664869E-05" />
    </inertial>
    <visual>
      <origin
        xyz="0 0 0"
        rpy="0 0 0" />
      <geometry>
        <mesh
          filename="package://wrist_base_link_1/meshes/Link_11.STL" />
      </geometry>
      <material
        name="">
        <color
          rgba="0.894117647058823 0.913725490196078 0.929411764705882 1" />
      </material>
    </visual>
    <collision>
      <origin
        xyz="0 0 0"
        rpy="0 0 0" />
      <geometry>
        <mesh
          filename="package://wrist_base_link_1/meshes/Link_11.STL" />
      </geometry>
    </collision>
  </link>
  <joint
    name="joint_11"
    type="revolute">
    <origin
      xyz="-0.00565 0.0003 -0.01515"
      rpy="3.1416 0 -3.1416" />
    <parent
      link="Link_1" />
    <child
      link="Link_11" />
    <axis
      xyz="0 0 -1" />
    <limit
      lower="-0.3955"
      upper="0.386"
      effort="10"
      velocity="1" />
  </joint>
  <link
    name="R_thumb_proximal_base">
    <inertial>
      <origin
        xyz="-0.0048772 -0.010163 0.00044069"
        rpy="0 -3.1415926 0" />
      <mass
        value="0.0018869" />
      <inertia
        ixx="5.2002E-08"
        ixy="4.8353E-09"
        ixz="-6.6441E-09"
        iyy="6.7433E-08"
        iyz="5.4472E-10"
        izz="8.5319E-08" />
    </inertial>
    <visual>
      <origin
        xyz="0 0 0"
        rpy="0 0 0" />
      <geometry>
        <mesh
          filename="package://wrist_base_link_1/meshes/R_thumb_proximal_base.STL" />
      </geometry>
      <material
        name="">
        <color
          rgba="1 1 1 1" />
      </material>
    </visual>
    <collision>
      <origin
        xyz="0 0 0"
        rpy="0 0 0" />
      <geometry>
        <mesh
          filename="package://wrist_base_link_1/meshes/R_thumb_proximal_base.STL" />
      </geometry>
    </collision>
  </link>
  <joint
    name="R_thumb_MCP_joint1"
    type="revolute">
    <origin
      xyz="0.020450106 0.016955517 -0.071693589"
      rpy="4.7124 0 3.605907533" />
    <parent
      link="Link_11" />
    <child
      link="R_thumb_proximal_base" />
    <axis
      xyz="0 -1 0" />
    <limit
      lower="0"
      upper="1.1"
      effort="50"
      velocity="1" />
  </joint>
  <link
    name="R_thumb_proximal">
    <inertial>
      <origin
        xyz="-3.8592E-05 0.02533 -0.0017007"
        rpy="0 0 0" />
      <mass
        value="0.0066075" />
      <inertia
        ixx="2.786E-06"
        ixy="1.673E-10"
        ixz="-1.3436E-09"
        iyy="8.9422E-07"
        iyz="-2.1394E-07"
        izz="2.4097E-06" />
    </inertial>
    <visual>
      <origin
        xyz="0 0 0"
        rpy="0 0 0" />
      <geometry>
        <mesh
          filename="package://wrist_base_link_1/meshes/R_thumb_proximal.STL" />
      </geometry>
      <material
        name="">
        <color
          rgba="1 1 1 1" />
      </material>
    </visual>
    <collision>
      <origin
        xyz="0 0 0"
        rpy="0 0 0" />
      <geometry>
        <mesh
          filename="package://wrist_base_link_1/meshes/R_thumb_proximal.STL" />
      </geometry>
    </collision>
  </link>
  <joint
    name="R_thumb_MCP_joint2"
    type="revolute">
    <origin
      xyz="-0.0115 -0.011843 0"
      rpy="5.55298075 1.5708 0" />
    <parent
      link="R_thumb_proximal_base" />
    <child
      link="R_thumb_proximal" />
    <axis
      xyz="1 0 0" />
    <limit
      lower="0"
      upper="0.5"
      effort="50"
      velocity="1" />
  </joint>
  <link
    name="R_thumb_intermediate">
    <inertial>
      <origin
        xyz="2.8437E-07 0.0072526 -0.0064293"
        rpy="0 0 0" />
      <mass
        value="0.0037847" />
      <inertia
        ixx="4.6531E-07"
        ixy="-3.454E-12"
        ixz="3.4344E-12"
        iyy="2.6858E-07"
        iyz="-6.414E-08"
        izz="4.2517E-07" />
    </inertial>
    <visual>
      <origin
        xyz="0 0 0"
        rpy="0 0 0" />
      <geometry>
        <mesh
          filename="package://wrist_base_link_1/meshes/R_thumb_intermediate.STL" />
      </geometry>
      <material
        name="">
        <color
          rgba="1 1 1 1" />
      </material>
    </visual>
    <collision>
      <origin
        xyz="0 0 0"
        rpy="0 0 0" />
      <geometry>
        <mesh
          filename="package://wrist_base_link_1/meshes/R_thumb_intermediate.STL" />
      </geometry>
    </collision>
  </link>
  <joint
    name="R_thumb_PIP_joint"
    type="revolute">
    <origin
      xyz="0 0.055863 0.0039241"
      rpy="-0.038299 0 0" />
    <parent
      link="R_thumb_proximal" />
    <child
      link="R_thumb_intermediate" />
    <axis
      xyz="1 0 0" />
    <limit
      lower="0"
      upper="1"
      effort="50"
      velocity="1" />
      <mimic 
        joint="R_thumb_MCP_joint2"
        multiplier="0.6"
        offset="0" />
  </joint>
  <link
    name="R_thumb_distal">
    <inertial>
      <origin
        xyz="-3.3054E-06 0.010511 -0.00057863"
        rpy="0 0 0" />
      <mass
        value="0.0033441" />
      <inertia
        ixx="2.0026E-07"
        ixy="-1.4303E-10"
        ixz="-5.6945E-11"
        iyy="8.711E-08"
        iyz="-2.4416E-08"
        izz="1.8974E-07" />
    </inertial>
    <visual>
      <origin
        xyz="0 0 0"
        rpy="0 0 0" />
      <geometry>
        <mesh
          filename="package://wrist_base_link_1/meshes/R_thumb_distal.STL" />
      </geometry>
      <material
        name="">
        <color
          rgba="1 1 1 1" />
      </material>
    </visual>
    <collision>
      <origin
        xyz="0 0 0"
        rpy="0 0 0" />
      <geometry>
        <mesh
          filename="package://wrist_base_link_1/meshes/R_thumb_distal.STL" />
      </geometry>
    </collision>
  </link>
  <joint
    name="R_thumb_DIP_joint"
    type="revolute">
    <origin
      xyz="0 0.022558 -0.0020717"
      rpy="-0.011642 0 0" />
    <parent
      link="R_thumb_intermediate" />
    <child
      link="R_thumb_distal" />
    <axis
      xyz="1 0 0" />
    <limit
      lower="0"
      upper="1.2"
      effort="50"
      velocity="1" />
      <mimic 
        joint="R_thumb_MCP_joint2"
        multiplier="0.8"
        offset="0" />
  </joint>
  <link
    name="R_index_proximal">
    <inertial>
      <origin
        xyz="0.0099008 0.011884 0.0016958"
        rpy="0 0 0" />
      <mass
        value="0.0042403" />
      <inertia
        ixx="6.9398E-07"
        ixy="-4.4846E-12"
        ixz="-3.0248E-12"
        iyy="2.3039E-07"
        iyz="-9.1779E-08"
        izz="6.434E-07" />
    </inertial>
    <visual>
      <origin
        xyz="0 0 0"
        rpy="0 0 0" />
      <geometry>
        <mesh
          filename="package://wrist_base_link_1/meshes/R_index_proximal.STL" />
      </geometry>
      <material
        name="">
        <color
          rgba="1 1 1 1" />
      </material>
    </visual>
    <collision>
      <origin
        xyz="0 0 0"
        rpy="0 0 0" />
      <geometry>
        <mesh
          filename="package://wrist_base_link_1/meshes/R_index_proximal.STL" />
      </geometry>
    </collision>
  </link>
  <joint
    name="R_index_MCP_joint"
    type="revolute">
    <origin
      xyz="0.016376106 -0.000284483 -0.137082589"
      rpy="4.4684 -0.034907 0" />
    <parent
      link="Link_11" />
    <child
      link="R_index_proximal" />
    <axis
      xyz="1 0 0" />
    <limit
      lower="0"
      upper="1.7"
      effort="50"
      velocity="1" />
  </joint>
  <link
    name="R_index_distal">
    <inertial>
      <origin
        xyz="0.0083258 0.019591 0.0019565"
        rpy="0 0 0" />
      <mass
        value="0.0045683" />
      <inertia
        ixx="7.8179E-07"
        ixy="9.0022E-13"
        ixz="5.6729E-13"
        iyy="1.5635E-07"
        iyz="-2.1007E-07"
        izz="7.0084E-07" />
    </inertial>
    <visual>
      <origin
        xyz="0 0 0"
        rpy="0 0 0" />
      <geometry>
        <mesh
          filename="package://wrist_base_link_1/meshes/R_index_distal.STL" />
      </geometry>
      <material
        name="">
        <color
          rgba="1 1 1 1" />
      </material>
    </visual>
    <collision>
      <origin
        xyz="0 0 0"
        rpy="0 0 0" />
      <geometry>
        <mesh
          filename="package://wrist_base_link_1/meshes/R_index_distal.STL" />
      </geometry>
    </collision>
  </link>
  <joint
    name="R_index_DIP_joint"
    type="revolute">
    <origin
      xyz="0.001575 0.030445 0.010275"
      rpy="0.044288 0 0" />
    <parent
      link="R_index_proximal" />
    <child
      link="R_index_distal" />
    <axis
      xyz="1 0 0" />
    <limit
      lower="0"
      upper="1.6"
      effort="50"
      velocity="1" />
      <mimic 
        joint="R_index_MCP_joint"
        multiplier="1"
        offset="0" />
  </joint>
  <link
    name="R_middle_proximal">
    <inertial>
      <origin
        xyz="0.008065 0.011884 0.0016958"
        rpy="0 0 0" />
      <mass
        value="0.0042403" />
      <inertia
        ixx="6.9397E-07"
        ixy="-6.0276E-12"
        ixz="-3.3971E-12"
        iyy="2.3039E-07"
        iyz="-9.1777E-08"
        izz="6.4339E-07" />
    </inertial>
    <visual>
      <origin
        xyz="0 0 0"
        rpy="0 0 0" />
      <geometry>
        <mesh
          filename="package://wrist_base_link_1/meshes/R_middle_proximal.STL" />
      </geometry>
      <material
        name="">
        <color
          rgba="1 1 1 1" />
      </material>
    </visual>
    <collision>
      <origin
        xyz="0 0 0"
        rpy="0 0 0" />
      <geometry>
        <mesh
          filename="package://wrist_base_link_1/meshes/R_middle_proximal.STL" />
      </geometry>
    </collision>
  </link>
  <joint
    name="R_middle_MCP_joint"
    type="revolute">
    <origin
      xyz="-0.001114894 -0.000284483 -0.137099589"
      rpy="4.4624 0 0" />
    <parent
      link="Link_11" />
    <child
      link="R_middle_proximal" />
    <axis
      xyz="1 0 0" />
    <limit
      lower="0"
      upper="1.68"
      effort="50"
      velocity="1" />
  </joint>
  <link
    name="R_middle_distal">
    <inertial>
      <origin
        xyz="0.0063978 0.020807 0.0018039"
        rpy="0 0 0" />
      <mass
        value="0.0050396" />
      <inertia
        ixx="9.8384E-07"
        ixy="5.3828E-12"
        ixz="3.4908E-12"
        iyy="1.7328E-07"
        iyz="-2.5594E-07"
        izz="8.914E-07" />
    </inertial>
    <visual>
      <origin
        xyz="0 0 0"
        rpy="0 0 0" />
      <geometry>
        <mesh
          filename="package://wrist_base_link_1/meshes/R_middle_distal.STL" />
      </geometry>
      <material
        name="">
        <color
          rgba="1 1 1 1" />
      </material>
    </visual>
    <collision>
      <origin
        xyz="0 0 0"
        rpy="0 0 0" />
      <geometry>
        <mesh
          filename="package://wrist_base_link_1/meshes/R_middle_distal.STL" />
      </geometry>
    </collision>
  </link>
  <joint
    name="R_middle_DIP_joint"
    type="revolute">
    <origin
      xyz="0.0016673 0.030445 0.010275"
      rpy="0.071413 0 0" />
    <parent
      link="R_middle_proximal" />
    <child
      link="R_middle_distal" />
    <axis
      xyz="1 0 0" />
    <limit
      lower="0"
      upper="1.6"
      effort="50"
      velocity="1" />
      <mimic 
        joint="R_middle_MCP_joint"
        multiplier="1"
        offset="0" />
  </joint>
  <link
    name="R_ring_proximal">
    <inertial>
      <origin
        xyz="0.0080207 0.011884 0.0016959"
        rpy="0 0 0" />
      <mass
        value="0.0042403" />
      <inertia
        ixx="6.9397E-07"
        ixy="-6.088E-12"
        ixz="-3.1846E-12"
        iyy="2.3039E-07"
        iyz="-9.1776E-08"
        izz="6.4339E-07" />
    </inertial>
    <visual>
      <origin
        xyz="0 0 0"
        rpy="0 0 0" />
      <geometry>
        <mesh
          filename="package://wrist_base_link_1/meshes/R_ring_proximal.STL" />
      </geometry>
      <material
        name="">
        <color
          rgba="1 1 1 1" />
      </material>
    </visual>
    <collision>
      <origin
        xyz="0 0 0"
        rpy="0 0 0" />
      <geometry>
        <mesh
          filename="package://wrist_base_link_1/meshes/R_ring_proximal.STL" />
      </geometry>
    </collision>
  </link>
  <joint
    name="R_ring_MCP_joint"
    type="revolute">
    <origin
      xyz="-0.020288894 -0.000284483 -0.136176589"
      rpy="4.4624 0.05236 0" />
    <parent
      link="Link_11" />
    <child
      link="R_ring_proximal" />
    <axis
      xyz="1 0 0" />
    <limit
      lower="0"
      upper="1.7"
      effort="50"
      velocity="1" />
  </joint>
  <link
    name="R_ring_distal">
    <inertial>
      <origin
        xyz="0.0080209 0.019591 0.0019565"
        rpy="0 0 0" />
      <mass
        value="0.0045683" />
      <inertia
        ixx="7.8177E-07"
        ixy="4.448E-13"
        ixz="7.2441E-13"
        iyy="1.5635E-07"
        iyz="-2.1007E-07"
        izz="7.0082E-07" />
    </inertial>
    <visual>
      <origin
        xyz="0 0 0"
        rpy="0 0 0" />
      <geometry>
        <mesh
          filename="package://wrist_base_link_1/meshes/R_ring_distal.STL" />
      </geometry>
      <material
        name="">
        <color
          rgba="1 1 1 1" />
      </material>
    </visual>
    <collision>
      <origin
        xyz="0 0 0"
        rpy="0 0 0" />
      <geometry>
        <mesh
          filename="package://wrist_base_link_1/meshes/R_ring_distal.STL" />
      </geometry>
    </collision>
  </link>
  <joint
    name="R_ring_DIP_joint"
    type="revolute">
    <origin
      xyz="0 0.030445 0.010275"
      rpy="0.039748 0 0" />
    <parent
      link="R_ring_proximal" />
    <child
      link="R_ring_distal" />
    <axis
      xyz="1 0 0" />
    <limit
      lower="0"
      upper="1.6"
      effort="50"
      velocity="1" />
      <mimic 
        joint="R_ring_MCP_joint"
        multiplier="1"
        offset="0" />
  </joint>
  <link
    name="R_pinky_proximal">
    <inertial>
      <origin
        xyz="0.0078887 0.011884 0.0016959"
        rpy="0 0 0" />
      <mass
        value="0.0042403" />
      <inertia
        ixx="6.9397E-07"
        ixy="-6.2993E-12"
        ixz="-3.3535E-12"
        iyy="2.3039E-07"
        iyz="-9.1776E-08"
        izz="6.4339E-07" />
    </inertial>
    <visual>
      <origin
        xyz="0 0 0"
        rpy="0 0 0" />
      <geometry>
        <mesh
          filename="package://wrist_base_link_1/meshes/R_pinky_proximal.STL" />
      </geometry>
      <material
        name="">
        <color
          rgba="1 1 1 1" />
      </material>
    </visual>
    <collision>
      <origin
        xyz="0 0 0"
        rpy="0 0 0" />
      <geometry>
        <mesh
          filename="package://wrist_base_link_1/meshes/R_pinky_proximal.STL" />
      </geometry>
    </collision>
  </link>
  <joint
    name="R_pinky_MCP_joint"
    type="revolute">
    <origin
      xyz="-0.039300894 -0.000028483 -0.134262589"
      rpy="4.4624 0.10472 0" />
    <parent
      link="Link_11" />
    <child
      link="R_pinky_proximal" />
    <axis
      xyz="1 0 0" />
    <limit
      lower="0"
      upper="1.7"
      effort="50"
      velocity="1" />
  </joint>
  <link
    name="R_pinky_distal">
    <inertial>
      <origin
        xyz="0.0078857 0.016239 0.0022243"
        rpy="0 0 0" />
      <mass
        value="0.0035996" />
      <inertia
        ixx="4.4867E-07"
        ixy="6.675E-11"
        ixz="-1.9009E-11"
        iyy="1.2248E-07"
        iyz="-1.3511E-07"
        izz="3.8689E-07" />
    </inertial>
    <visual>
      <origin
        xyz="0 0 0"
        rpy="0 0 0" />
      <geometry>
        <mesh
          filename="package://wrist_base_link_1/meshes/R_pinky_distal.STL" />
      </geometry>
      <material
        name="">
        <color
          rgba="1 1 1 1" />
      </material>
    </visual>
    <collision>
      <origin
        xyz="0 0 0"
        rpy="0 0 0" />
      <geometry>
        <mesh
          filename="package://wrist_base_link_1/meshes/R_pinky_distal.STL" />
      </geometry>
    </collision>
  </link>
  <joint
    name="R_pinky_DIP_joint"
    type="revolute">
    <origin
      xyz="0 0.030445 0.010275"
      rpy="-0.037691 0 0" />
    <parent
      link="R_pinky_proximal" />
    <child
      link="R_pinky_distal" />
    <axis
      xyz="1 0 0" />
    <limit
      lower="0"
      upper="1.6"
      effort="50"
      velocity="1" />
      <mimic 
        joint="R_pinky_MCP_joint"
        multiplier="1"
        offset="0" />
  </joint>
</robot>

